mythril.ethereum.util [ERROR]: Encountered a decode error.
 stdout:
 stderr: b''
{"success": false, "error": "Traceback (most recent call last):\n  File \"/home/ubuntu/private-mythril/mythril/interfaces/cli.py\", line 968, in parse_args_and_execute\n    address = load_code(disassembler, args)\n  File \"/home/ubuntu/private-mythril/mythril/interfaces/cli.py\", line 719, in load_code\n    address, _ = disassembler.load_from_solidity(\n  File \"/home/ubuntu/private-mythril/mythril/mythril/mythril_disassembler.py\", line 255, in load_from_solidity\n    self.sigs.import_solidity_file(\n  File \"/home/ubuntu/private-mythril/mythril/support/signatures.py\", line 245, in import_solidity_file\n    solc_json = get_solc_json(file_path, solc_binary, solc_settings_json)\n  File \"/home/ubuntu/private-mythril/mythril/ethereum/util.py\", line 102, in get_solc_json\n    raise e\n  File \"/home/ubuntu/private-mythril/mythril/ethereum/util.py\", line 99, in get_solc_json\n    result = json.loads(out)\n  File \"/usr/lib/python3.10/json/__init__.py\", line 346, in loads\n    return _default_decoder.decode(s)\n  File \"/usr/lib/python3.10/json/decoder.py\", line 337, in decode\n    obj, end = self.raw_decode(s, idx=_w(s, 0).end())\n  File \"/usr/lib/python3.10/json/decoder.py\", line 355, in raw_decode\n    raise JSONDecodeError(\"Expecting value\", s, err.value) from None\njson.decoder.JSONDecodeError: Expecting value: line 1 column 1 (char 0)\n", "issues": []}
1.35user 1.21system 0:01.23elapsed 208%CPU (0avgtext+0avgdata 112588maxresident)k
928inputs+24outputs (4major+22761minor)pagefaults 0swaps
